Workbook

Sheet Mode d'emploi
A1: MODE D'EMPLOI DE LA FICHE DE COÛT INSTN
A5: Code couleurs des onglets :
A6: onglets bleus : fiche de coût référence pour les formations/prestations "mono-unité" et fiche de coût pour l'unité "pilote" si formation/prestation "multi-unités"
A7: onglets roses (partenaire1) --> à n'utiliser que pour les formations/prestations impliquant au moins deux unités
A8: onglets orange (partenaire2) --> à n'utiliser que pour les formations/prestations impliquant trois unités
A9: onglet vert (consolidation) --> fiche de coût référence pour les formations "multi-unités" donnant les coûts et tarifs de la formation / prestation
A10: onglets sans couleurs : mode d'emploi + table de référence des programmes/projets/OS/thèmes FC ou libellés FD
A12: Code couleurs de la fiche de coûts :
A13: cellule sans couleur --> saisie possible
A14: cellule orange --> calculée automatiquement
A15: cellule grise --> ne pas utiliser
A17: Grande zones de la fiche de coûts
... A28: Coûts frais déplacements --> aide au chiffrage : attention les montants ne remontent pas automatiquement et sont à ressaisir dans la fiche de coûts

Sheet Table OS Formations
A1: PROGRAMME | B1: PROJET OU PROGRAMME | C1: ORDRE STAT | D1: THEME (FC) OU LIBELLE FORMATION (FD) | E1: FC/FD | G1: Couleurs
A2: xxxxx | B2: xxxxx | C2: Choisir OS | D2: xxxxx | E2: xxxxx
A3: xxxxx | B3: xxxxx | C3: Inexistant : OS à créer | D3: xxxxx | E3: xxxxx
A4: xxxxx | B4: xxxxx | C4: OS spécifique existant : à saisir | D4: xxxxx | E4: xxxxx
A5: INGÉNIERIE NUCLÉAIRE | B5: 01 - Génie des réacteurs nucléaires | C5: LOCFORMDGAXX | D5: ING - Ingénieur spécialisé en Génie atomique (GA) | E5: FD | G5: FD | I5: Projet 01
C6: LOCTHREACNUC | D6: Réacteurs nucléaires | E6: FC | G6: FC | I6: Projet 01
C7: LOCTHREACREP | D7: Filière réacteurs à eau sous pression (REP) | E7: FC | I7: Projet 01
B8: 02 - Réacteurs de 4e génération | C8: LOCFORMDGPNX | D8: M2 - Génie des procédés appliqués au nucléaire (GPN) | E8: FD | I8: Projet 02
C9: LOCTHSODASDM | D9: École du sodium et des métaux liquides - Assainissement et démantèlement | E9: FC | I9: Projet 02
C10: LOCTHSODEXPL | D10: École du sodium et des métaux liquides - Exploitation | E10: FC | I10: Projet 02
C11: LOCTHSYSTFUT | D11: Systèmes du futur | E11: FC | I11: Projet 02
B12: 03 - Combustible nucléaire et génie des procédés | C12: LOCTHCYCOMBU | D12: Cycle du combustible | E12: FC | I12: Projet 03
C13: LOCFORMDCSMP | D13: M2 - Chimie séparative, matériaux et procédés : applications au cycle du combustible nucléaire (CSMP) | E13: FD | I13: Projet 03
C14: LOCFORMDMCNX | D14: LP - Métrologie chimique et nucléaire (MCN) | E14: FD | I14: Projet 03
C15: LOCFORMDMNEX | D15: M2 – Master Nuclear Energy MNE (NRPE + DWM + FC + NPD + O + M1) | E15: FD | I15: Projet 03
C16: LOCFORMDPEEX | D16: M2 - Procédés, énergie, environnement (PEE) | E16: FD | I16: Projet 03
C17: LOCTHSURVINE | D17: Surveillance des installations nucléaires et de l'environnement | E17: FC | I17: Projet 03
B18: 04 - Assainissement, démantèlement et gestion des déchets | C18: LOCTHASSAINT | D18: Assainissement | E18: FC | I18: Projet 04
C19: LOCTHDEMANTT | D19: Démantèlement | E19: FC | I19: Projet 04
C20: LOCFORMDL3DX | D20: LP - Métiers du DEM, du désamiantage, de la dépollution des déchets (L3D) | E20: FD | I20: Projet 04
C21: LOCTHGESDECH | D21: Gestion des déchets | E21: FC | I21: Projet 04
B22: 05 - Réacteurs de recherche et instrumentation | C22: LOCTHDETECME | D22: Détection et mesures | E22: FC | I22: Projet 05
C23: LOCFORMDIMEX | D23: M2 - Instrumentation des moyens d'essai (IME) | E23: FD | I23: Projet 05
C24: LOCFORMDTPEX | D24: LP - Techniques physiques des énergies (TPE) | E24: FD | I24: Projet 05
C25: LOCTHREACEXP | D25: Réacteurs expérimentaux | E25: FC | I25: Projet 05
C26: LOCTHSTATMES | D26: Statistiques appliquées aux mesures | E26: FC | I26: Projet 05
B27: 06 - Exploitation, sûreté et maintenance des installations nucléaires | C27: LOCTHEXPMAIN | D27: Exploitation et maintenance nucléaire | E27: FC | I27: Projet 06
C28: LOCFORMDGINX | D28: ING - Ingénieur en Génie des installations nucléaires (GIN) | E28: FD | I28: Projet 06
C29: LOCTHFORMCOM | D29: Formations communes aux intervenants du nucléaire | E29: FC | I29: Projet 06
C30: LOCTHGESTIMN | D30: Gestion des matières nucléaires | E30: FC | I30: Projet 06
C31: LOCTHIMPACTS | D31: Impacts environnementaux des activités industrielles | E31: FC | I31: Projet 06
C32: LOCTHPREVRIS | D32: Prévention des risques | E32: FC | I32: Projet 06
C33: LOCTHPROSURN | D33: Professionnels de la sûreté nucléaire | E33: FC | I33: Projet 06
C34: LOCTHPROTECI | D34: Équipements de protection individuelle | E34: FC | I34: Projet 06
C35: LOCTHSECCONV | D35: Sécurité conventionnelle dans les installations nucléaires | E35: FC | I35: Projet 06
C36: LOCTHSURPEIN | D36: Sûreté des personnels des installations nucléaires | E36: FC | I36: Projet 06
B37: 07 - Plasmas - Fusion | C37: LOCFORMDSPFX | D37: M2 – FedSPF (SFP + GI + PPF) | E37: FD | I37: Projet 07
C38: LOCFORMDIFCE | D38: Cours IFCEN | E38: FD | I38: Program 01
C39: LOCFORMDINSU | D39: M2 - Pro Ingénierie pour le nucléaire de Sorbonne Université | E39: FD | I39: Program 01
C40: LOCFORMDVALE | D40: M2 - Ingénierie nucléaire de Valence (ADIN + GEDERA + SN) | E40: FD | I40: Program 01
...

Sheet Fiche de coûts
A1: Fiche de coûts INSTN - V1.4 du 25/01/2019
E3: MAJ : 12/12/19
B5: Libellé de la formation ou de la prestation | C5: Télémanipulation | J5: Prix de vente CEA | K5: Prix de vente hors CEA minimum | L5: =CONCATENATE("Prix de vente hors CEA préconisé avec taux de marge de ",C15*100,"%") -> Prix de vente hors CEA préconisé avec taux de marge de 10% | T5: Code formation | U5: Intitulé formation | V5: Nombre de jours par session | W5: Prix 2020 | X5: Prix remisé 2020 | Y5: Seuil couverture frais externes avec prix standard | Z5: Seuil couverture frais externes avec prix remisé | AA5: Seuil rentabilité coût direct avec prix standard | AB5: Seuil rentabilité coût direct avec prix remisé | AC5: Seuil rentabilité coût complet avec prix standard | AD5: Seuil rentabilité coût complet avec prix remisé | AE5: Temps passé RP (A1) hors conception en heures | AF5: Dont enseigne-ment | AG5: Temps passé AF (A2) en heures | AH5: Montant des vacations (€) | AI5: Frais variables par stagiaire (€)
B6: Code IRIS de la formation (si existant, sinon ne rien indiquer) | C6: TEL | G6: Coût par session / prestation hors aléas | J6: =K29 -> 6334.06 | K6: =L29 -> 8400.9272 | L6: =K6*(1+C15) -> 9241.0199 | T6: =C6 -> TEL | U6: =C5 -> Télémanipulation | V6: =C9 -> 3 | W6: =J18 -> 1390 | X6: =J17 -> 1251 | Y6: =Q14 -> 1 | Z6: =Q13 -> 2 | AA6: =Q18 -> 3 | AB6: =Q17 -> 4 | AC6: =Q22 -> 6 | AD6: =Q21 -> 7 | AE6: =C97 -> 3 | AF6: =C67+C68+C69 -> 0 | AG6: =D97 -> 12 | AH6: =H97 -> 877.31 | AI6: =N8 -> 560.71429
B7: Date de création de la formation (JJ/MM/AAAA) | C7: 36161 | G7: Dont part fixe | J7: =K53+K97-K80-K81-K82-K83-K84-K85-K86-K87-K88 -> 2409.06 | K7: =L53+L97-L80-L81-L82-L83-L84-L85-L86-L87-L88 -> 4342.4772 | L7: =K7*(1+C15) -> 4776.7249 | N7: part variable par stagiaire
B8: Type de formation (menu déroulant) | C8: FC INTER | G8: Dont part variable | J8: =K80+K81+K82+K83+K84+K85+K86+K87+K88 -> 3925 | K8: =L80+L81+L82+L83+L84+L85+L86+L87+L88 -> 4058.45 | L8: =K8*(1+C15) -> 4464.295 | N8: =J8/C14 -> 560.71429 | O8: légèrement variable à cause des +2 dans le nombre de repas
B9: Durée de la session en jours (pour formation continue) | C9: 3 | G9: Aléas 10% | J9: =ROUND(J6*0.1,0) -> 633 | K9: =ROUND(K6*0.1,0) -> 840 | L9: =ROUND(L6*0.1,0) -> 924
B10: Nom du responsable pédagogique | C10: J.VIDECOQ | G10: Coût par session avec aléas | J10: =J6+J9 -> 6967.06 | K10: =K6+K9 -> 9240.9272 | L10: =L6+L9 -> 10165.02
B11: Code OS de la formation (menu déroulant lié à onglet "table OS") | C11: LOCTHEXPMAIN | G11: Coût par participant | J11: =ROUND(J10/C14,0) -> 995 | K11: =ROUND(K10/C14,0) -> 1320 | L11: =ROUND(L10/C14,0) -> 1452 | P11: Une fois le prix fixé
B12: Numéro de programme ou projet INSTN (lien auto si OS renseigné) | C12: =IF(LEFT(C11,3)<>"LOC","A saisir",VLOOKUP(C11,'Table OS Formations'!C:I,7,FALSE)) -> Projet 06 | D12: cf. onglet "table OS" | G12: Coût par jour | J12: =IF(OR(LEFT(C8,2)="FC",LEFT(C8,2)="Ce"),ROUND(J10/C9,0),"Non applicable") -> 2322 | K12: =IF(OR(LEFT(C8,2)="FC",LEFT(C8,2)="Ce"),ROUND(K10/C9,0),"Non applicable") -> 3080 | L12: =IF(OR(LEFT(C8,2)="FC",LEFT(C8,2)="Ce"),ROUND(L10/C9,0),"Non applicable") -> 3388 | P12: Nbre participants mini pour couverture frais externes
B13: Unité INSTN (menu déroulant)*** | C13: UEM | G13: Coût par jour et par participant | J13: =IF(LEFT(J12,1)="N",J12,ROUND(J12/C14,0)) -> 332 | K13: =IF(LEFT(K12,1)="N",K12,ROUND(K12/C14,0)) -> 440 | L13: =IF(LEFT(L12,1)="N",L12,ROUND(L12/C14,0)) -> 484 | P13: CEA | Q13: =ROUNDUP(Q$28/N17,0) -> 2 | T13: Coûts installation : 0 si pas pris en compte, 1 si pris en compte
B14: Nombre de participants prévu | C14: 7 | G14: Nombre de participants minimum | J14: =ROUNDUP(J7/(J11-J8/C14),0) -> 6 | K14: =ROUNDUP(J7/(K11-J8/C14),0) -> 4 | L14: =ROUNDUP(J7/(L11-J8/C14),0) -> 3 | P14: non CEA | Q14: =ROUNDUP(Q$28/N18,0) -> 1 | T14: 0
B15: Taux de marge pour prix de vente hors CEA préconisé | C15: 0.1 | D15: Taux de marge de 10% à | G15: CA pour nombre participants minimum | J15: =J11*J14 -> 5970 | K15: =K11*K14 -> 5280 | L15: =L11*L14 -> 4356
D16: modifier si nécessaire | G16: Coût T1 pour participants minimum | J16: =ROUND(J7+J8/C14*J14,0) -> 5773 | K16: =ROUND(J7+J8/C14*K14,0) -> 4652 | L16: =ROUND(J7+J8/C14*L14,0) -> 4091 | N16: prix/stagiaire-part variable | P16: Nbre participants mini pour couverture coût direct INSTN
B17: *** si plusieurs unités, saisir cette fiche de coût pour unité pilote + fiche(s) de coûts unité(s) partenaire(s) et voir vision complète sur feuille "fiche de coût conso" | G17: Prix de vente définitif client CEA fixé | J17: =0.9*J18 -> 1251 | K17: remise 10% | N17: =J17-J8/C14 -> 690.28571 | P17: CEA | Q17: =ROUNDUP((K$29-J8)/N17,0) -> 4
G18: Prix de vente définitif client externe fixé | J18: 1390 | K18: prix 2020 | N18: =J18-J8/C14 -> 829.28571 | P18: non CEA | Q18: =ROUNDUP((K$29-J8)/N18,0) -> 3
G20: En cas d'exclusion du coût de conception des chiffrages ci-dessus (ie. si durée amo conception choisie = 0) : | P20: Nbre participants mini pour couverture coût complet CEA
G21: Montant total de conception à facturer | J21: =IF(I50=0,K49,0) -> 0 | K21: =IF(I50=0,L49,0) -> 0 | L21: =IF(I50=0,M49,0) -> 0 | P21: CEA | Q21: =ROUNDUP((L$29-J8)/N17,0) -> 7
G22: Soit montant de conception par jour | J22: =IF(OR(LEFT(C8,2)="FC",LEFT(C8,2)="Ce"),ROUND(J21/C9,0),"Non applicable") -> 0 | K22: =IF(OR(LEFT(C8,2)="FC",LEFT(C8,2)="Ce"),ROUND(K21/C9,0),"Non applicable") -> 0 | L22: =IF(OR(LEFT(C8,2)="FC",LEFT(C8,2)="Ce"),ROUND(L21/C9,0),"Non applicable") -> 0 | P22: non CEA | Q22: =ROUNDUP((L$29-J8)/N18,0) -> 6
G23: Soit montant de conception par participant | J23: =J21/C14 -> 0 | K23: =K21/C14 -> 0 | L23: =L21/C14 -> 0
G24: Soit conception par jour et par participant | J24: =IF(LEFT(J22,1)="N","Non applicable",ROUND(J23/C9,0)) -> 0 | K24: =IF(LEFT(K22,1)="N","Non applicable",ROUND(K23/C9,0)) -> 0 | L24: =IF(LEFT(K22,1)="N","Non applicable",ROUND(K23/C9,0)) -> 0
Q25: HORS INSTALLATION
K26: Coût direct INSTN | L26: Coût complet CEA | M26: Coût complet INSTN pour information | P26: Frais externes | Q26: Frais externes fixes | T26: Frais externes fixes | U26: Frais variables par stagiaire | W26: Coût direct - part fixe | Y26: Frais variables par stagiaires avec TVA NR | Z26: Coût complet - part fixe | AB26: Seuil couverture frais externes avec prix standard | AC26: Seuil couverture frais externes avec prix remisé | AD26: Seuil rentabilité coût direct avec prix standard | AE26: Seuil rentabilité coût direct avec prix remisé | AF26: Seuil rentabilité coût complet avec prix standard | AG26: Seuil rentabilité coût complet avec prix remisé | AH26: Temps passé RP (A1) hors conception en heures | AI26: Dont enseigne-ment | AJ26: Temps passé AF (A2) en heures | AK26: Montant des vacations (€)
A27: Rubrique | B27: Poste de dépenses | C27: INSTN A1* (taux T1) En heures | D27: INSTN A2* (taux T1) En heures | E27: Montant MO INSTN (taux T1) En € | F27: Vacataire CEA En heures | G27: Vacataire non CEA En heures | H27: Montant des vacations En € | I27: Frais de déplacement ** En € | J27: Autres dépenses HT En € | K27: Coût direct T1 par session FC (ou promo FD) (taux T1) | L27: Coût environné T3 (taux T3 + TVA NR) | M27: Coût environné T2 (T1 + CID INSTN) | P27: Coût direct T1 - MO CT T1 | Q27: Part fixe - MO CT T1 | T27: =Q28 -> 767.23 | U27: =N8 -> 560.71429 | W27: =J7 -> 2409.06 | Y27: =U27*(1+$C$112) -> 579.77857 | Z27: =K7 -> 4342.4772 | AB27: =Q14 -> 1 | AC27: =Q13 -> 2 | AD27: =Q18 -> 3 | AE27: =Q17 -> 4 | AF27: =Q22 -> 6 | AG27: =Q21 -> 7 | AH27: =C97 -> 3 | AI27: =C67+C68+C69 -> 0 | AJ27: =D97 -> 12 | AK27: =H97 -> 877.31
P28: =K29-C97*C108-D97*C109-C53*C97-D53*C108 -> 5432.23 | Q28: =J7-C97*C108-D97*C109-C53*C97-D53*C108-J76-J78 -> 767.23
A29: Coût total de la session / promo hors aléas (quote-part phase de conception + phase de réalisation) | K29: =K53+K97 -> 6334.06 | L29: =L53+L97 -> 8400.9272 | M29: =M53+M97 -> 8072.8537
A31: Phase de conception - (moyens totaux pour toutes les sessions)
A32: Analyse d'opportunité | B32: Réalisation de l'avant-projet / processus offre | E32: =C32*C108+C109*D32 -> 0 | K32: =SUM(E32:J32)-F32-G32 -> 0 | L32: =E32*(1+C110)+I32+J32*(1+C112) -> 0 | M32: =E32*(1+C119)+I32+J32 -> 0
B33: Temps passé communication et reporting | E33: =C33*C108+C109*D33 -> 0 | K33: =SUM(E33:J33)-F33-G33 -> 0 | L33: =E33*(1+C110)+I33+J33*(1+C112) -> 0 | M33: =E33*(1+C119)+I33+J33 -> 0
A34: Elaboration de la certification | B34: Analyse des besoins | E34: =C34*C108+C109*D34 -> 0 | K34: =SUM(E34:J34)-F34-G34 -> 0 | L34: =E34*(1+C110)+I34+J34*(1+C112) -> 0 | M34: =E34*(1+C119)+I34+J34 -> 0
B35: Définition du référentiel d'activités professionnelles | E35: =C35*C108+C109*D35 -> 0 | K35: =SUM(E35:J35)-F35-G35 -> 0 | L35: =E35*(1+C110)+I35+J35*(1+C112) -> 0 | M35: =E35*(1+C119)+I35+J35 -> 0
B36: Définition du référentiel de compétences | E36: =C36*C108+C109*D36 -> 0 | K36: =SUM(E36:J36)-F36-G36 -> 0 | L36: =E36*(1+C110)+I36+J36*(1+C112) -> 0 | M36: =E36*(1+C119)+I36+J36 -> 0
B37: Définition du référentiel de certification | E37: =C37*C108+C109*D37 -> 0 | K37: =SUM(E37:J37)-F37-G37 -> 0 | L37: =E37*(1+C110)+I37+J37*(1+C112) -> 0 | M37: =E37*(1+C119)+I37+J37 -> 0
A38: Conception | B38: Conception du projet pédagogique | E38: =C38*C108+C109*D38 -> 0 | K38: =SUM(E38:J38)-F38-G38 -> 0 | L38: =E38*(1+C110)+I38+J38*(1+C112) -> 0 | M38: =E38*(1+C119)+I38+J38 -> 0
B39: Elaboration du contenu de la formation | E39: =C39*C108+C109*D39 -> 0 | K39: =SUM(E39:J39)-F39-G39 -> 0 | L39: =E39*(1+C110)+I39+J39*(1+C112) -> 0 | M39: =E39*(1+C119)+I39+J39 -> 0
B40: Conception des supports pédagogiques | E40: =C40*C108+C109*D40 -> 0 | K40: =SUM(E40:J40)-F40-G40 -> 0 | L40: =E40*(1+C110)+I40+J40*(1+C112) -> 0 | M40: =E40*(1+C119)+I40+J40 -> 0
B41: Libellé libre phase de conception à saisir si besoin | E41: =C41*C108+C109*D41 -> 0 | K41: =SUM(E41:J41)-F41-G41 -> 0 | L41: =E41*(1+C110)+I41+J41*(1+C112) -> 0 | M41: =E41*(1+C119)+I41+J41 -> 0
B42: Libellé libre phase de conception à saisir si besoin | E42: =C42*C108+C109*D42 -> 0 | K42: =SUM(E42:J42)-F42-G42 -> 0 | L42: =E42*(1+C110)+I42+J42*(1+C112) -> 0 | M42: =E42*(1+C119)+I42+J42 -> 0
B43: Libellé libre phase de conception à saisir si besoin | E43: =C43*C108+C109*D43 -> 0 | K43: =SUM(E43:J43)-F43-G43 -> 0 | L43: =E43*(1+C110)+I43+J43*(1+C112) -> 0 | M43: =E43*(1+C119)+I43+J43 -> 0
B44: Libellé libre phase de conception à saisir si besoin | E44: =C44*C108+C109*D44 -> 0 | K44: =SUM(E44:J44)-F44-G44 -> 0 | L44: =E44*(1+C110)+I44+J44*(1+C112) -> 0 | M44: =E44*(1+C119)+I44+J44 -> 0
...

Sheet Coûts installations
A1: Coût des installations
A3: TP - Coût par jour | B3: Coût HT | C3: Quantité | D3: Montant
A4: Chantier école CHE | B4: 1000 | D4: =B4*C4 -> 0
A5: Chantier école MAR | B5: 1000 | D5: =B5*C5 -> 0
A6: Chantier école SAC | B6: 1000 | D6: =B6*C6 -> 0
A7: EVOC | B7: 5000 | D7: =B7*C7 -> 0
A8: Radiochimie | B8: 1000 | D8: =B8*C8 -> 0
A9: Autre (préciser Coût HT) | D9: =B9*C9 -> 0
A10: Montant TP reporté sur fiche de coût | D10: =SUM(D4:D9) -> 0
A13: Montant salles /outils pédagos reporté sur fiche de coût | D13: =B18*C18+B19*C19+B20*C20+B21*C21+B22*C22+B23*C23+D18*E18+D19*E19+D20*E20+D21*E21+D22*E22+D23*E23+F18*G18+F19*G19+F20*G20+F21*G21+F22*G22+F23*G23+H18*I18+H19*I19+H20*I20+H21*I21+H22*I22+H23*I23+B29*C29+B30*C30+B31*C31+B32*C32+D29*E29+D30*E30+D31*E31+D32*E32+F29*G29+F30*G30+F31*G31+F32*G32+H29*I29+H30*I30+H31*I31+H32*I32+B37*C37+B38*C38+B39*C39+B40*C40+D37*E37+D38*E38+D39*E39+D40*E40+F37*G37+F38*G38+F39*G39+F40*G40+H37*I37+H38*I38+H39*I39+H40*I40+B45*C45+B46*C46+B47*C47+B48*C48+B49*C49+B50*C50+B51*C51+B52*C52+B54*C54+B55*C55+B56*C56+B57*C57+D45*E45+D46*E46+D47*E47+D48*E48+D49*E49+D50*E50+D51*E51+D52*E52+D54*E54+D55*E55+D56*E56+D57*E57+F45*G45+F46*G46+F47*G47+F48*G48+F49*G49+F50*G50+F51*G51+F52*G52+F53*G53+F54*G54+F55*G55+F56*G56+F57*G57+H45*I45+H46*I46+H47*I47+H48*I48+H49*I49+H50*I50+H51*I51+H52*I52+H53*I53+H54*I54+H55*I55+H56*I56+H57*I57+C61*D61+C62*D62+C63*D63+C64*D64+C65*D65+C66*D66+C67*D67+C68*D68+C69*D69+C70*D70+C71*D71+C72*D72+C73*D73+C74*D74+E61*F61+E62*F62+E63*F63+E64*F64+E65*F65+E66*F66+E67*F67+E68*F68+E69*F69+E70*F70+E71*F71+E72*F72+E73*F73+E74*F74 -> 740
B15: Jour | F15: 1/2 Jour
A16: Salles - valeurs moyennes | B16: Client non CEA | D16: Client CEA (remise 20%) | F16: Client non CEA | H16: Client CEA (remise 20%)
B17: Coût | C17: Quantité | D17: Coût | E17: Quantité | F17: Coût | G17: Quantité | H17: Coût | I17: Quantité
A18: Salle < 26 | B18: 370 | C18: 2 | D18: =ROUND(B18*0.8,0) -> 296 | F18: =ROUND(B18*0.65,0) -> 241 | H18: =ROUND(F18*0.8,0) -> 193
A19: Salle < 50 | B19: 700 | D19: =ROUND(B19*0.8,0) -> 560 | F19: =ROUND(B19*0.65,0) -> 455 | H19: =ROUND(F19*0.8,0) -> 364
A20: Salle 50 à 80 cours | B20: 1050 | D20: =ROUND(B20*0.8,0) -> 840 | F20: =ROUND(B20*0.65,0) -> 683 | H20: =ROUND(F20*0.8,0) -> 546
A21: Salle > 80 | B21: 1300 | D21: =ROUND(B21*0.8,0) -> 1040 | F21: =ROUND(B21*0.65,0) -> 845 | H21: =ROUND(F21*0.8,0) -> 676
A22: Salle TP ou informatique | B22: 800 | D22: =ROUND(B22*0.8,0) -> 640 | F22: =ROUND(B22*0.65,0) -> 520 | H22: =ROUND(F22*0.8,0) -> 416
A23: Autre (préciser Coût HT) | D23: =ROUND(B23*0.8,0) -> 0 | F23: =ROUND(B23*0.65,0) -> 0 | H23: =ROUND(F23*0.8,0) -> 0
B26: Jour | F26: 1/2 Jour
A27: Salles UEC | B27: Client non CEA | D27: Client CEA (remise 20%) | F27: Client non CEA | H27: Client CEA (remise 20%)
B28: Coût | C28: Quantité | D28: Coût | E28: Quantité | F28: Coût | G28: Quantité | H28: Coût | I28: Quantité
A29: Amphi | B29: 1600 | D29: =ROUND(B29*0.8,0) -> 1280 | F29: 900 | H29: =ROUND(F29*0.8,0) -> 720
A30: H1 | B30: 550 | D30: =ROUND(B30*0.8,0) -> 440 | F30: 350 | H30: =ROUND(F30*0.8,0) -> 280
A31: H2 | B31: 420 | D31: =ROUND(B31*0.8,0) -> 336 | F31: 270 | H31: =ROUND(F31*0.8,0) -> 216
A32: Autres salles UEC | B32: 440 | D32: =ROUND(B32*0.8,0) -> 352 | F32: 290 | H32: =ROUND(F32*0.8,0) -> 232
B34: Jour | F34: 1/2 Jour
A35: Salles UEM | B35: Client non CEA | D35: Client CEA (remise 20%) | F35: Client non CEA | H35: Client CEA (remise 20%)
B36: Coût | C36: Quantité | D36: Coût | E36: Quantité | F36: Coût | G36: Quantité | H36: Coût | I36: Quantité
A37: Salle de cours 40 personnes | B37: 500 | D37: =ROUND(B37*0.8,0) -> 400 | F37: 300 | H37: =ROUND(F37*0.8,0) -> 240
A38: Salle de cours 30 personnes | B38: 400 | D38: =ROUND(B38*0.8,0) -> 320 | F38: 250 | H38: =ROUND(F38*0.8,0) -> 200
A39: Salle de cours 19 personnes | B39: 400 | D39: =ROUND(B39*0.8,0) -> 320 | F39: 250 | H39: =ROUND(F39*0.8,0) -> 200
A40: Salle informatique 8 PC | B40: 620 | D40: =ROUND(B40*0.8,0) -> 496 | F40: 370 | H40: =ROUND(F40*0.8,0) -> 296
B42: Jour | F42: 1/2 Jour
A43: Salles UES | B43: Client non CEA | D43: Client CEA (remise 20%) | F43: Client non CEA | H43: Client CEA (remise 20%)
B44: Coût | C44: Quantité | D44: Coût | E44: Quantité | F44: Coût | G44: Quantité | H44: Coût | I44: Quantité
A45: Salle de cours < 26 places écoles | B45: 370 | D45: =ROUND(B45*0.8,0) -> 296 | F45: 222 | H45: =ROUND(F45*0.8,0) -> 178
A46: Salle de cours < 50 places écoles | B46: 700 | D46: =ROUND(B46*0.8,0) -> 560 | F46: 420 | H46: =ROUND(F46*0.8,0) -> 336
A47: Salle de cours de 72 à 80 places écoles | B47: 1050 | D47: =ROUND(B47*0.8,0) -> 840 | F47: 630 | H47: =ROUND(F47*0.8,0) -> 504
A48: Salle Eichner 120 places écoles | B48: 1300 | D48: =ROUND(B48*0.8,0) -> 1040 | F48: 780 | H48: =ROUND(F48*0.8,0) -> 624
...

Sheet Coûts frais variables
A1: Coûts frais variables
A3: Repas - coût unitaire | B3: Coût unitaire HT | C3: Nombre de pauses par participant sur l'ensemble de la formation | D3: Nombre Participants saisi sur fiche de coût | E3: Montant
A4: Repas Rotonde (participants + 2) | B4: 17.5 | D4: ='Fiche de coûts'!C14+2 -> 9 | E4: =B4*D4*C4 -> 0
A5: Repas restaurant (participants + 2) | B5: 12.5 | C5: 3 | D5: ='Fiche de coûts'!C14+2 -> 9 | E5: =B5*D5*C5 -> 337.5
A6: Pause café standard | B6: 6 | D6: ='Fiche de coûts'!C14 -> 7 | E6: =B6*D6*C6 -> 0
A7: Autre (préciser prix HT) | D7: ='Fiche de coûts'!C14 -> 7 | E7: =B7*D7*C7 -> 0
A8: Montant repas reporté sur fiche de coût | E8: =SUM(E4:E7) -> 337.5
A11: Supports de formation - coût unitaire | B11: Coût unitaire HT | C11: Nombre de supports ou de matériel par participant | D11: Nombre Participants saisi sur fiche de coût | E11: Montant reporté sur fiche de coût
A12: Supports de formation (livres, CD, clés USB, tablettes…) (prix unitaire à corriger si besoin) | B12: 15 | D12: ='Fiche de coûts'!C14 -> 7 | E12: =B12*D12*C12 -> 0
A13: Polycopiés (100 pages par participant) | B13: 25 | C13: 0.5 | D13: ='Fiche de coûts'!C14 -> 7 | E13: =B13*D13*C13 -> 87.5 | F13: =B13*C13 -> 12.5
A14: Pochettes ou boîtes | B14: 5 | D14: ='Fiche de coûts'!C14 -> 7 | E14: =B14*D14*C14 -> 0
A15: Autre support de formation (préciser prix HT) | D15: ='Fiche de coûts'!C14 -> 7 | E15: =B15*D15*C15 -> 0
A16: Accès au télémanipulateur (500 € par stagiaire) | B16: 500 | C16: 1 | D16: ='Fiche de coûts'!C14 -> 7 | E16: =B16*D16*C16 -> 3500
A17: Libellé libre frais variable à saisir si besoin (onglet frais var) | D17: ='Fiche de coûts'!C14 -> 7 | E17: =B17*D17*C17 -> 0
A18: Libellé libre frais variable à saisir si besoin (onglet frais var) | D18: ='Fiche de coûts'!C14 -> 7 | E18: =B18*D18*C18 -> 0
A19: Libellé libre frais variable à saisir si besoin (onglet frais var) | D19: ='Fiche de coûts'!C14 -> 7 | E19: =B19*D19*C19 -> 0

Sheet Coûts frais déplacement
A1: Coûts frais de déplacement
A2: (aide pour le chiffrage : barème CEA)
C5: Région parisienne | E5: Province | G5: Etranger | I5: Montant à reporter sur fiche de coût
A6: Type de frais | B6: Unité | C6: Coût | D6: Quantité | E6: Coût | F6: Quantité | G6: Coût | H6: Quantité
A7: Frais de déplacement | B7: km | C7: 0.32 | E7: 0.32 | G7: 0 | I7: =C7*D7+E7*F7+G7*H7 -> 0
A8: Hébergement | B8: nuitée | C8: 92 | E8: 72 | G8: 0 | I8: =C8*D8+E8*F8+G8*H8 -> 0
A9: Restauration soir | B9: EUR | C9: 22 | E9: 22 | G9: 0 | I9: =C9*D9+E9*F9+G9*H9 -> 0
A10: Restauration midi | B10: EUR | C10: 17.5 | E10: 17.5 | G10: 0 | I10: =C10*D10+E10*F10+G10*H10 -> 0
A11: Autre (préciser prix HT) | B11: EUR | E11: =ROUND(C11*0.65,0) -> 0 | G11: =ROUND(E11*0.65,0) -> 0 | I11: =C11*D11+E11*F11+G11*H11 -> 0
I12: =SUM(I7:I11) -> 0
A13: Attention : montants qui ne remontent pas dans la fiche de coût (simple aide à la saisie)

Sheet Fiche de coûts part1
A1: ='Fiche de coûts'!A1:M1 -> Fiche de coûts INSTN - V1.4 du 25/01/2019
C3: Partenaire 1
B5: Libellé de la formation ou de la prestation | C5: ='Fiche de coûts'!C5:F5 -> Télémanipulation | J5: Prix de vente CEA | K5: Prix de vente hors CEA minimum | L5: =CONCATENATE("Prix de vente hors CEA préconisé avec taux de marge de ",C15*100,"%") -> Prix de vente hors CEA préconisé avec taux de marge de 10%
B6: Code IRIS de la formation (si existant, sinon ne rien indiquer) | C6: ='Fiche de coûts'!C6:F6 -> TEL | G6: Coût par session / prestation hors aléas | J6: =K29 -> 0 | K6: =L29 -> 0 | L6: =K6*(1+C15) -> 0
B7: Date de création de la formation (JJ/MM/AAAA) | C7: ='Fiche de coûts'!C7:F7 -> 36161 | G7: Dont part fixe | J7: =K53+K97-K80-K81-K82-K83-K84-K85-K86-K87-K88 -> 0 | K7: =L53+L97-L80-L81-L82-L83-L84-L85-L86-L87-L88 -> 0 | L7: =K7*(1+C15) -> 0
B8: Type de formation (menu déroulant) | C8: ='Fiche de coûts'!C8:F8 -> FC INTER | G8: Dont part variable | J8: =K80+K81+K82+K83+K84+K85+K86+K87+K88 -> 0 | K8: =L80+L81+L82+L83+L84+L85+L86+L87+L88 -> 0 | L8: =K8*(1+C15) -> 0
B9: Durée de la session en jours (pour formation continue) | C9: ='Fiche de coûts'!C9:F9 -> 3 | G9: Aléas 10% | J9: =ROUND(J6*0.1,0) -> 0 | K9: =ROUND(K6*0.1,0) -> 0 | L9: =ROUND(L6*0.1,0) -> 0
B10: Nom du responsable pédagogique | C10: ='Fiche de coûts'!C10:F10 -> J.VIDECOQ | G10: Coût par session avec aléas | J10: =J6+J9 -> 0 | K10: =K6+K9 -> 0 | L10: =L6+L9 -> 0
B11: Code OS de la formation (cf. onglet "table OS") | C11: ='Fiche de coûts'!C11:F11 -> LOCTHEXPMAIN | G11: Coût par participant | J11: =ROUND(J10/C14,0) -> 0 | K11: =ROUND(K10/C14,0) -> 0 | L11: =ROUND(L10/C14,0) -> 0
B12: Numéro de programme ou projet INSTN (cf. onglet "table OS") | C12: ='Fiche de coûts'!C12:F12 -> Projet 06 | G12: Coût par jour | J12: =IF(OR(LEFT(C8,2)="FC",LEFT(C8,2)="Ce"),ROUND(J10/C9,0),"Non applicable") -> 0 | K12: =IF(OR(LEFT(C8,2)="FC",LEFT(C8,2)="Ce"),ROUND(K10/C9,0),"Non applicable") -> 0 | L12: =IF(OR(LEFT(C8,2)="FC",LEFT(C8,2)="Ce"),ROUND(L10/C9,0),"Non applicable") -> 0
B13: Unité INSTN (menu déroulant)*** | C13: Choisir Unité | G13: Coût par jour et par participant | J13: =IF(LEFT(J12,1)="N",J12,ROUND(J12/C14,0)) -> 0 | K13: =IF(LEFT(K12,1)="N",K12,ROUND(K12/C14,0)) -> 0 | L13: =IF(LEFT(L12,1)="N",L12,ROUND(L12/C14,0)) -> 0
B14: Nombre de participants prévu | C14: ='Fiche de coûts'!C14:F14 -> 7 | G14: Nombre de participants minimum | J14: =ROUNDUP(J7/(J11-J8/C14),0) -> #DIV/0! | K14: =ROUNDUP(J7/(K11-J8/C14),0) -> #DIV/0! | L14: =ROUNDUP(J7/(L11-J8/C14),0) -> #DIV/0!
B15: Taux de marge pour prix de vente hors CEA préconisé | C15: ='Fiche de coûts'!C15:F15 -> 0.1 | D15: Taux de marge de 10% à | G15: CA pour nombre participants minimum | J15: =J11*J14 -> #DIV/0! | K15: =K11*K14 -> #DIV/0! | L15: =L11*L14 -> #DIV/0!
D16: modifier si nécessaire | G16: Coût T1 pour participants minimum | J16: =ROUND(J7+J8/C14*J14,0) -> #DIV/0! | K16: =ROUND(J7+J8/C14*K14,0) -> #DIV/0! | L16: =ROUND(J7+J8/C14*L14,0) -> #DIV/0!
B17: *** fiche de coût part. 1 à utiliser uniquement en cas de prestation multi-unités --> vision complète sur "fiche de coût conso" | G17: Prix de vente définitif client CEA fixé | J17: A saisir | K17: (part du prix de vente partenaire 1)
G18: Prix de vente définitif client externe fixé | J18: A saisir
G20: En cas d'exclusion du coût de conception des chiffrages ci-dessus (ie. si durée amo conception choisie = 0) :
G21: Montant total de conception à facturer | J21: =IF(I50=0,K49,0) -> 0 | K21: =IF(I50=0,L49,0) -> 0 | L21: =IF(I50=0,M49,0) -> 0
G22: Soit montant de conception par jour | J22: =IF(OR(LEFT(C8,2)="FC",LEFT(C8,2)="Ce"),ROUND(J21/C9,0),"Non applicable") -> 0 | K22: =IF(OR(LEFT(C8,2)="FC",LEFT(C8,2)="Ce"),ROUND(K21/C9,0),"Non applicable") -> 0 | L22: =IF(OR(LEFT(C8,2)="FC",LEFT(C8,2)="Ce"),ROUND(L21/C9,0),"Non applicable") -> 0
G23: Soit montant de conception par participant | J23: =J21/C14 -> 0 | K23: =K21/C14 -> 0 | L23: =L21/C14 -> 0
G24: Soit conception par jour et par participant | J24: =IF(LEFT(J22,1)="N","Non applicable",ROUND(J23/C9,0)) -> 0 | K24: =IF(LEFT(K22,1)="N","Non applicable",ROUND(K23/C9,0)) -> 0 | L24: =IF(LEFT(K22,1)="N","Non applicable",ROUND(K23/C9,0)) -> 0
K26: Coût direct INSTN | L26: Coût complet CEA | M26: Coût complet INSTN pour information
A27: Rubrique | B27: Poste de dépenses | C27: INSTN A1* (taux T1) En heures | D27: INSTN A2* (taux T1) En heures | E27: Montant MO INSTN (taux T1) En € | F27: Vacataire CEA En heures | G27: Vacataire non CEA En heures | H27: Montant des vacations En € | I27: Frais de déplacement ** En € | J27: Autres dépenses HT En € | K27: Coût direct T1 par session FC (ou promo FD) (taux T1) | L27: Coût environné T3 (taux T3 + TVA NR) | M27: Coût environné T2 (T1 + CID INSTN)
A29: Coût total de la session / promo hors aléas (quote-part phase de conception + phase de réalisation) | K29: =K53+K97 -> 0 | L29: =L53+L97 -> 0 | M29: =M53+M97 -> 0
A31: Phase de conception - (moyens totaux pour toutes les sessions)
A32: Analyse d'opportunité | B32: Réalisation de l'avant-projet / processus offre | E32: =C32*C108+C109*D32 -> 0 | K32: =SUM(E32:J32)-F32-G32 -> 0 | L32: =E32*(1+C110)+I32+J32*(1+C112) -> 0 | M32: =E32*(1+C119)+I32+J32 -> 0
B33: Temps passé communication et reporting | E33: =C33*C108+C109*D33 -> 0 | K33: =SUM(E33:J33)-F33-G33 -> 0 | L33: =E33*(1+C110)+I33+J33*(1+C112) -> 0 | M33: =E33*(1+C119)+I33+J33 -> 0
A34: Elaboration de la certification | B34: Analyse des besoins | E34: =C34*C108+C109*D34 -> 0 | K34: =SUM(E34:J34)-F34-G34 -> 0 | L34: =E34*(1+C110)+I34+J34*(1+C112) -> 0 | M34: =E34*(1+C119)+I34+J34 -> 0
B35: Définition du référentiel d'activités professionnelles | E35: =C35*C108+C109*D35 -> 0 | K35: =SUM(E35:J35)-F35-G35 -> 0 | L35: =E35*(1+C110)+I35+J35*(1+C112) -> 0 | M35: =E35*(1+C119)+I35+J35 -> 0
B36: Définition du référentiel de compétences | E36: =C36*C108+C109*D36 -> 0 | K36: =SUM(E36:J36)-F36-G36 -> 0 | L36: =E36*(1+C110)+I36+J36*(1+C112) -> 0 | M36: =E36*(1+C119)+I36+J36 -> 0
B37: Définition du référentiel de certification | E37: =C37*C108+C109*D37 -> 0 | K37: =SUM(E37:J37)-F37-G37 -> 0 | L37: =E37*(1+C110)+I37+J37*(1+C112) -> 0 | M37: =E37*(1+C119)+I37+J37 -> 0
A38: Conception | B38: Conception du projet pédagogique | E38: =C38*C108+C109*D38 -> 0 | K38: =SUM(E38:J38)-F38-G38 -> 0 | L38: =E38*(1+C110)+I38+J38*(1+C112) -> 0 | M38: =E38*(1+C119)+I38+J38 -> 0
B39: Elaboration du contenu de la formation | E39: =C39*C108+C109*D39 -> 0 | K39: =SUM(E39:J39)-F39-G39 -> 0 | L39: =E39*(1+C110)+I39+J39*(1+C112) -> 0 | M39: =E39*(1+C119)+I39+J39 -> 0
B40: Conception des supports pédagogiques | E40: =C40*C108+C109*D40 -> 0 | K40: =SUM(E40:J40)-F40-G40 -> 0 | L40: =E40*(1+C110)+I40+J40*(1+C112) -> 0 | M40: =E40*(1+C119)+I40+J40 -> 0
B41: Libellé libre phase de conception à saisir si besoin | E41: =C41*C108+C109*D41 -> 0 | K41: =SUM(E41:J41)-F41-G41 -> 0 | L41: =E41*(1+C110)+I41+J41*(1+C112) -> 0 | M41: =E41*(1+C119)+I41+J41 -> 0
B42: Libellé libre phase de conception à saisir si besoin | E42: =C42*C108+C109*D42 -> 0 | K42: =SUM(E42:J42)-F42-G42 -> 0 | L42: =E42*(1+C110)+I42+J42*(1+C112) -> 0 | M42: =E42*(1+C119)+I42+J42 -> 0
B43: Libellé libre phase de conception à saisir si besoin | E43: =C43*C108+C109*D43 -> 0 | K43: =SUM(E43:J43)-F43-G43 -> 0 | L43: =E43*(1+C110)+I43+J43*(1+C112) -> 0 | M43: =E43*(1+C119)+I43+J43 -> 0
B44: Libellé libre phase de conception à saisir si besoin | E44: =C44*C108+C109*D44 -> 0 | K44: =SUM(E44:J44)-F44-G44 -> 0 | L44: =E44*(1+C110)+I44+J44*(1+C112) -> 0 | M44: =E44*(1+C119)+I44+J44 -> 0
B45: Rédaction cahier des charges pour sous-traitants | E45: =C45*C108+C109*D45 -> 0 | K45: =SUM(E45:J45)-F45-G45 -> 0 | L45: =E45*(1+C110)+I45+J45*(1+C112) -> 0 | M45: =E45*(1+C119)+I45+J45 -> 0
B46: Sélection et qualification des intervenants | E46: =C46*C108+C109*D46 -> 0 | K46: =SUM(E46:J46)-F46-G46 -> 0 | L46: =E46*(1+C110)+I46+J46*(1+C112) -> 0 | M46: =E46*(1+C119)+I46+J46 -> 0
...

Sheet Coûts installations part1
A1: Coût des installations
A3: TP - Coût par jour | B3: Coût HT | C3: Quantité | D3: Montant
A4: Chantier école CHE | B4: 1000 | D4: =B4*C4 -> 0
A5: Chantier école MAR | B5: 1000 | D5: =B5*C5 -> 0
A6: Chantier école SAC | B6: 1000 | D6: =B6*C6 -> 0
A7: EVOC | B7: 5000 | D7: =B7*C7 -> 0
A8: Radiochimie | B8: 1000 | D8: =B8*C8 -> 0
A9: Autre (préciser Coût HT) | D9: =B9*C9 -> 0
A10: Montant TP reporté sur fiche de coût | D10: =SUM(D4:D9) -> 0
A13: Montant salles /outils pédagos reporté sur fiche de coût | D13: =B18*C18+B19*C19+B20*C20+B21*C21+B22*C22+B23*C23+D18*E18+D19*E19+D20*E20+D21*E21+D22*E22+D23*E23+F18*G18+F19*G19+F20*G20+F21*G21+F22*G22+F23*G23+H18*I18+H19*I19+H20*I20+H21*I21+H22*I22+H23*I23+B29*C29+B30*C30+B31*C31+B32*C32+D29*E29+D30*E30+D31*E31+D32*E32+F29*G29+F30*G30+F31*G31+F32*G32+H29*I29+H30*I30+H31*I31+H32*I32+B37*C37+B38*C38+B39*C39+B40*C40+D37*E37+D38*E38+D39*E39+D40*E40+F37*G37+F38*G38+F39*G39+F40*G40+H37*I37+H38*I38+H39*I39+H40*I40+B45*C45+B46*C46+B47*C47+B48*C48+B49*C49+B50*C50+B51*C51+B52*C52+B54*C54+B55*C55+B56*C56+B57*C57+D45*E45+D46*E46+D47*E47+D48*E48+D49*E49+D50*E50+D51*E51+D52*E52+D54*E54+D55*E55+D56*E56+D57*E57+F45*G45+F46*G46+F47*G47+F48*G48+F49*G49+F50*G50+F51*G51+F52*G52+F53*G53+F54*G54+F55*G55+F56*G56+F57*G57+H45*I45+H46*I46+H47*I47+H48*I48+H49*I49+H50*I50+H51*I51+H52*I52+H53*I53+H54*I54+H55*I55+H56*I56+H57*I57+C61*D61+C62*D62+C63*D63+C64*D64+C65*D65+C66*D66+C67*D67+C68*D68+C69*D69+C70*D70+C71*D71+C72*D72+C73*D73+C74*D74+E61*F61+E62*F62+E63*F63+E64*F64+E65*F65+E66*F66+E67*F67+E68*F68+E69*F69+E70*F70+E71*F71+E72*F72+E73*F73+E74*F74 -> 0
B15: Jour | F15: 1/2 Jour
A16: Salles - valeurs moyennes | B16: Client non CEA | D16: Client CEA (remise 20%) | F16: Client non CEA | H16: Client CEA (remise 20%)
B17: Coût | C17: Quantité | D17: Coût | E17: Quantité | F17: Coût | G17: Quantité | H17: Coût | I17: Quantité
A18: Salle < 26 | B18: 370 | D18: =ROUND(B18*0.8,0) -> 296 | F18: =ROUND(B18*0.65,0) -> 241 | H18: =ROUND(F18*0.8,0) -> 193
A19: Salle < 50 | B19: 700 | D19: =ROUND(B19*0.8,0) -> 560 | F19: =ROUND(B19*0.65,0) -> 455 | H19: =ROUND(F19*0.8,0) -> 364
A20: Salle 50 à 80 cours | B20: 1050 | D20: =ROUND(B20*0.8,0) -> 840 | F20: =ROUND(B20*0.65,0) -> 683 | H20: =ROUND(F20*0.8,0) -> 546
A21: Salle > 80 | B21: 1300 | D21: =ROUND(B21*0.8,0) -> 1040 | F21: =ROUND(B21*0.65,0) -> 845 | H21: =ROUND(F21*0.8,0) -> 676
A22: Salle TP ou informatique | B22: 800 | D22: =ROUND(B22*0.8,0) -> 640 | F22: =ROUND(B22*0.65,0) -> 520 | H22: =ROUND(F22*0.8,0) -> 416
A23: Autre (préciser Coût HT) | D23: =ROUND(B23*0.8,0) -> 0 | F23: =ROUND(B23*0.65,0) -> 0 | H23: =ROUND(F23*0.8,0) -> 0
B26: Jour | F26: 1/2 Jour
A27: Salles UEC | B27: Client non CEA | D27: Client CEA (remise 20%) | F27: Client non CEA | H27: Client CEA (remise 20%)
B28: Coût | C28: Quantité | D28: Coût | E28: Quantité | F28: Coût | G28: Quantité | H28: Coût | I28: Quantité
A29: Amphi | B29: 1600 | D29: =ROUND(B29*0.8,0) -> 1280 | F29: 900 | H29: =ROUND(F29*0.8,0) -> 720
A30: H1 | B30: 550 | D30: =ROUND(B30*0.8,0) -> 440 | F30: 350 | H30: =ROUND(F30*0.8,0) -> 280
A31: H2 | B31: 420 | D31: =ROUND(B31*0.8,0) -> 336 | F31: 270 | H31: =ROUND(F31*0.8,0) -> 216
A32: Autres salles UEC | B32: 440 | D32: =ROUND(B32*0.8,0) -> 352 | F32: 290 | H32: =ROUND(F32*0.8,0) -> 232
B34: Jour | F34: 1/2 Jour
A35: Salles UEM | B35: Client non CEA | D35: Client CEA (remise 20%) | F35: Client non CEA | H35: Client CEA (remise 20%)
B36: Coût | C36: Quantité | D36: Coût | E36: Quantité | F36: Coût | G36: Quantité | H36: Coût | I36: Quantité
A37: Salle de cours 40 personnes | B37: 500 | D37: =ROUND(B37*0.8,0) -> 400 | F37: 300 | H37: =ROUND(F37*0.8,0) -> 240
A38: Salle de cours 30 personnes | B38: 400 | D38: =ROUND(B38*0.8,0) -> 320 | F38: 250 | H38: =ROUND(F38*0.8,0) -> 200
A39: Salle de cours 19 personnes | B39: 400 | D39: =ROUND(B39*0.8,0) -> 320 | F39: 250 | H39: =ROUND(F39*0.8,0) -> 200
A40: Salle informatique 8 PC | B40: 620 | D40: =ROUND(B40*0.8,0) -> 496 | F40: 370 | H40: =ROUND(F40*0.8,0) -> 296
B42: Jour | F42: 1/2 Jour
A43: Salles UES | B43: Client non CEA | D43: Client CEA (remise 20%) | F43: Client non CEA | H43: Client CEA (remise 20%)
B44: Coût | C44: Quantité | D44: Coût | E44: Quantité | F44: Coût | G44: Quantité | H44: Coût | I44: Quantité
A45: Salle de cours < 26 places écoles | B45: 370 | D45: =ROUND(B45*0.8,0) -> 296 | F45: 222 | H45: =ROUND(F45*0.8,0) -> 178
A46: Salle de cours < 50 places écoles | B46: 700 | D46: =ROUND(B46*0.8,0) -> 560 | F46: 420 | H46: =ROUND(F46*0.8,0) -> 336
A47: Salle de cours de 72 à 80 places écoles | B47: 1050 | D47: =ROUND(B47*0.8,0) -> 840 | F47: 630 | H47: =ROUND(F47*0.8,0) -> 504
A48: Salle Eichner 120 places écoles | B48: 1300 | D48: =ROUND(B48*0.8,0) -> 1040 | F48: 780 | H48: =ROUND(F48*0.8,0) -> 624
...

Sheet Coûts frais variables part1
A1: Coûts frais variables
A3: Repas - coût unitaire | B3: Coût unitaire HT | C3: Nombre de pauses par participant sur l'ensemble de la formation | D3: Nombre Participants saisi sur fiche de coût | E3: Montant
A4: Repas Rotonde (participants + 2) | B4: 17.5 | D4: ='Fiche de coûts part1'!C14+2 -> 9 | E4: =B4*D4*C4 -> 0
A5: Repas restaurant (participants + 2) | B5: 12.5 | D5: ='Fiche de coûts part1'!C14+2 -> 9 | E5: =B5*D5*C5 -> 0
A6: Pause café standard | B6: 6 | D6: ='Fiche de coûts part1'!C14 -> 7 | E6: =B6*D6*C6 -> 0
A7: Autre (préciser prix HT) | D7: ='Fiche de coûts part1'!C14 -> 7 | E7: =B7*D7*C7 -> 0
A8: Montant repas reporté sur fiche de coût | E8: =SUM(E4:E7) -> 0
A11: Supports de formation - coût unitaire | B11: Coût unitaire HT | C11: Nombre de supports ou de matériel par participant | D11: Nombre Participants saisi sur fiche de coût | E11: Montant reporté sur fiche de coût
A12: Supports de formation (livres, CD, clés USB, tablettes…) (prix unitaire à corriger si besoin) | B12: 15 | D12: ='Fiche de coûts part1'!C14 -> 7 | E12: =B12*D12*C12 -> 0
A13: Polycopiés (100 pages par participant) | B13: 25 | D13: ='Fiche de coûts part1'!C14 -> 7 | E13: =B13*D13*C13 -> 0
A14: Pochettes ou boîtes | B14: 5 | D14: ='Fiche de coûts part1'!C14 -> 7 | E14: =B14*D14*C14 -> 0
A15: Autre support de formation(préciser prix HT) | D15: ='Fiche de coûts part1'!C14 -> 7 | E15: =B15*D15*C15 -> 0
A16: Libellé libre frais variable à saisir si besoin (onglet frais var) | D16: ='Fiche de coûts part1'!C14 -> 7 | E16: =B16*D16*C16 -> 0
A17: Libellé libre frais variable à saisir si besoin (onglet frais var) | D17: ='Fiche de coûts part1'!C14 -> 7 | E17: =B17*D17*C17 -> 0
A18: Libellé libre frais variable à saisir si besoin (onglet frais var) | D18: ='Fiche de coûts part1'!C14 -> 7 | E18: =B18*D18*C18 -> 0
A19: Libellé libre frais variable à saisir si besoin (onglet frais var) | D19: ='Fiche de coûts part1'!C14 -> 7 | E19: =B19*D19*C19 -> 0

Sheet Coûts frais déplacement part1
A1: Coûts frais de déplacement
A2: (aide pour le chiffrage : barème CEA)
C5: Région parisienne | E5: Province | G5: Etranger | I5: Montant à reporter sur fiche de coût
A6: Type de frais | B6: Unité | C6: Coût | D6: Quantité | E6: Coût | F6: Quantité | G6: Coût | H6: Quantité
A7: Frais de déplacement | B7: km | C7: 0.32 | E7: 0.32 | G7: 0 | I7: =C7*D7+E7*F7+G7*H7 -> 0
A8: Hébergement | B8: nuitée | C8: 92 | E8: 72 | G8: 0 | I8: =C8*D8+E8*F8+G8*H8 -> 0
A9: Restauration soir | B9: EUR | C9: 22 | E9: 22 | G9: 0 | I9: =C9*D9+E9*F9+G9*H9 -> 0
A10: Restauration midi | B10: EUR | C10: 17.5 | E10: 17.5 | G10: 0 | I10: =C10*D10+E10*F10+G10*H10 -> 0
A11: Autre (préciser prix HT) | B11: EUR | E11: =ROUND(C11*0.65,0) -> 0 | G11: =ROUND(E11*0.65,0) -> 0 | I11: =C11*D11+E11*F11+G11*H11 -> 0
I12: =SUM(I7:I11) -> 0
A13: Attention : montants qui ne remontent pas dans la fiche de coût (simple aide à la saisie)

Sheet Fiche de coûts part2
A1: ='Fiche de coûts part1'!A1:M1 -> Fiche de coûts INSTN - V1.4 du 25/01/2019
C3: Partenaire 2
B5: Libellé de la formation ou de la prestation | C5: ='Fiche de coûts'!C5:F5 -> Télémanipulation | J5: Prix de vente CEA | K5: Prix de vente hors CEA minimum | L5: =CONCATENATE("Prix de vente hors CEA préconisé avec taux de marge de ",C15*100,"%") -> Prix de vente hors CEA préconisé avec taux de marge de 10%
B6: Code IRIS de la formation (si existant, sinon ne rien indiquer) | C6: ='Fiche de coûts'!C6:F6 -> TEL | G6: Coût par session / prestation hors aléas | J6: =K29 -> 0 | K6: =L29 -> 0 | L6: =K6*(1+C15) -> 0
B7: Date de création de la formation (JJ/MM/AAAA) | C7: ='Fiche de coûts'!C7:F7 -> 36161 | G7: Dont part fixe | J7: =K53+K97-K80-K81-K82-K83-K84-K85-K86-K87-K88 -> 0 | K7: =L53+L97-L80-L81-L82-L83-L84-L85-L86-L87-L88 -> 0 | L7: =K7*(1+C15) -> 0
B8: Type de formation (menu déroulant) | C8: ='Fiche de coûts'!C8:F8 -> FC INTER | G8: Dont part variable | J8: =K80+K81+K82+K83+K84+K85+K86+K87+K88 -> 0 | K8: =L80+L81+L82+L83+L84+L85+L86+L87+L88 -> 0 | L8: =K8*(1+C15) -> 0
B9: Durée de la session en jours (pour formation continue) | C9: ='Fiche de coûts'!C9:F9 -> 3 | G9: Aléas 10% | J9: =ROUND(J6*0.1,0) -> 0 | K9: =ROUND(K6*0.1,0) -> 0 | L9: =ROUND(L6*0.1,0) -> 0
B10: Nom du responsable pédagogique (à modifier si besoin) | C10: ='Fiche de coûts'!C10:F10 -> J.VIDECOQ | G10: Coût par session avec aléas | J10: =J6+J9 -> 0 | K10: =K6+K9 -> 0 | L10: =L6+L9 -> 0
B11: Code OS de la formation (cf. onglet "table OS") | C11: ='Fiche de coûts'!C11:F11 -> LOCTHEXPMAIN | D11: ='Fiche de coûts'!D11:G11 -> 0 | E11: ='Fiche de coûts'!E11:H11 -> 0 | G11: Coût par participant | J11: =ROUND(J10/C14,0) -> 0 | K11: =ROUND(K10/C14,0) -> 0 | L11: =ROUND(L10/C14,0) -> 0
B12: Numéro de programme ou projet INSTN (cf. onglet "table OS") | C12: ='Fiche de coûts'!C12:F12 -> Projet 06 | G12: Coût par jour | J12: =IF(OR(LEFT(C8,2)="FC",LEFT(C8,2)="Ce"),ROUND(J10/C9,0),"Non applicable") -> 0 | K12: =IF(OR(LEFT(C8,2)="FC",LEFT(C8,2)="Ce"),ROUND(K10/C9,0),"Non applicable") -> 0 | L12: =IF(OR(LEFT(C8,2)="FC",LEFT(C8,2)="Ce"),ROUND(L10/C9,0),"Non applicable") -> 0
B13: Unité INSTN (menu déroulant)*** | C13: Choisir Unité | G13: Coût par jour et par participant | J13: =IF(LEFT(J12,1)="N",J12,ROUND(J12/C14,0)) -> 0 | K13: =IF(LEFT(K12,1)="N",K12,ROUND(K12/C14,0)) -> 0 | L13: =IF(LEFT(L12,1)="N",L12,ROUND(L12/C14,0)) -> 0
B14: Nombre de participants prévu | C14: ='Fiche de coûts'!C14:F14 -> 7 | G14: Nombre de participants minimum | J14: =ROUNDUP(J7/(J11-J8/C14),0) -> #DIV/0! | K14: =ROUNDUP(J7/(K11-J8/C14),0) -> #DIV/0! | L14: =ROUNDUP(J7/(L11-J8/C14),0) -> #DIV/0!
B15: Taux de marge pour prix de vente hors CEA préconisé | C15: ='Fiche de coûts'!C15:F15 -> 0.1 | D15: Taux de marge de 10% à | G15: CA pour nombre participants minimum | J15: =J11*J14 -> #DIV/0! | K15: =K11*K14 -> #DIV/0! | L15: =L11*L14 -> #DIV/0!
D16: modifier si nécessaire | G16: Coût T1 pour participants minimum | J16: =ROUND(J7+J8/C14*J14,0) -> #DIV/0! | K16: =ROUND(J7+J8/C14*K14,0) -> #DIV/0! | L16: =ROUND(J7+J8/C14*L14,0) -> #DIV/0!
B17: *** fiche de coût part. 2 à utiliser uniquement en cas de prestation multi-unités --> vision complète sur "fiche de coût conso" | G17: Prix de vente définitif client CEA fixé | J17: A saisir | K17: (part du prix de vente partenaire 2)
G18: Prix de vente définitif client externe fixé | J18: A saisir
G20: En cas d'exclusion du coût de conception des chiffrages ci-dessus (ie. si durée amo conception choisie = 0) :
G21: Montant total de conception à facturer | J21: =IF(I50=0,K49,0) -> 0 | K21: =IF(I50=0,L49,0) -> 0 | L21: =IF(I50=0,M49,0) -> 0
G22: Soit montant de conception par jour | J22: =IF(OR(LEFT(C8,2)="FC",LEFT(C8,2)="Ce"),ROUND(J21/C9,0),"Non applicable") -> 0 | K22: =IF(OR(LEFT(C8,2)="FC",LEFT(C8,2)="Ce"),ROUND(K21/C9,0),"Non applicable") -> 0 | L22: =IF(OR(LEFT(C8,2)="FC",LEFT(C8,2)="Ce"),ROUND(L21/C9,0),"Non applicable") -> 0
G23: Soit montant de conception par participant | J23: =J21/C14 -> 0 | K23: =K21/C14 -> 0 | L23: =L21/C14 -> 0
G24: Soit conception par jour et par participant | J24: =IF(LEFT(J22,1)="N","Non applicable",ROUND(J23/C9,0)) -> 0 | K24: =IF(LEFT(K22,1)="N","Non applicable",ROUND(K23/C9,0)) -> 0 | L24: =IF(LEFT(K22,1)="N","Non applicable",ROUND(K23/C9,0)) -> 0
K26: Coût direct INSTN | L26: Coût complet CEA | M26: Coût complet INSTN pour information
A27: Rubrique | B27: Poste de dépenses | C27: INSTN A1* (taux T1) En heures | D27: INSTN A2* (taux T1) En heures | E27: Montant MO INSTN (taux T1) En € | F27: Vacataire CEA En heures | G27: Vacataire non CEA En heures | H27: Montant des vacations En € | I27: Frais de déplacement ** En € | J27: Autres dépenses HT En € | K27: Coût direct T1 par session FC (ou promo FD) (taux T1) | L27: Coût environné T3 (taux T3 + TVA NR) | M27: Coût environné T2 (T1 + CID INSTN)
A29: Coût total de la session / promo hors aléas (quote-part phase de conception + phase de réalisation) | K29: =K53+K97 -> 0 | L29: =L53+L97 -> 0 | M29: =M53+M97 -> 0
A31: Phase de conception - (moyens totaux pour toutes les sessions)
A32: Analyse d'opportunité | B32: Réalisation de l'avant-projet / processus offre | E32: =C32*C108+C109*D32 -> 0 | K32: =SUM(E32:J32)-F32-G32 -> 0 | L32: =E32*(1+C110)+I32+J32*(1+C112) -> 0 | M32: =E32*(1+C119)+I32+J32 -> 0
B33: Temps passé communication et reporting | E33: =C33*C108+C109*D33 -> 0 | K33: =SUM(E33:J33)-F33-G33 -> 0 | L33: =E33*(1+C110)+I33+J33*(1+C112) -> 0 | M33: =E33*(1+C119)+I33+J33 -> 0
A34: Elaboration de la certification | B34: Analyse des besoins | E34: =C34*C108+C109*D34 -> 0 | K34: =SUM(E34:J34)-F34-G34 -> 0 | L34: =E34*(1+C110)+I34+J34*(1+C112) -> 0 | M34: =E34*(1+C119)+I34+J34 -> 0
B35: Définition du référentiel d'activités professionnelles | E35: =C35*C108+C109*D35 -> 0 | K35: =SUM(E35:J35)-F35-G35 -> 0 | L35: =E35*(1+C110)+I35+J35*(1+C112) -> 0 | M35: =E35*(1+C119)+I35+J35 -> 0
B36: Définition du référentiel de compétences | E36: =C36*C108+C109*D36 -> 0 | K36: =SUM(E36:J36)-F36-G36 -> 0 | L36: =E36*(1+C110)+I36+J36*(1+C112) -> 0 | M36: =E36*(1+C119)+I36+J36 -> 0
B37: Définition du référentiel de certification | E37: =C37*C108+C109*D37 -> 0 | K37: =SUM(E37:J37)-F37-G37 -> 0 | L37: =E37*(1+C110)+I37+J37*(1+C112) -> 0 | M37: =E37*(1+C119)+I37+J37 -> 0
A38: Conception | B38: Conception du projet pédagogique | E38: =C38*C108+C109*D38 -> 0 | K38: =SUM(E38:J38)-F38-G38 -> 0 | L38: =E38*(1+C110)+I38+J38*(1+C112) -> 0 | M38: =E38*(1+C119)+I38+J38 -> 0
B39: Elaboration du contenu de la formation | E39: =C39*C108+C109*D39 -> 0 | K39: =SUM(E39:J39)-F39-G39 -> 0 | L39: =E39*(1+C110)+I39+J39*(1+C112) -> 0 | M39: =E39*(1+C119)+I39+J39 -> 0
B40: Conception des supports pédagogiques | E40: =C40*C108+C109*D40 -> 0 | K40: =SUM(E40:J40)-F40-G40 -> 0 | L40: =E40*(1+C110)+I40+J40*(1+C112) -> 0 | M40: =E40*(1+C119)+I40+J40 -> 0
B41: Libellé libre phase de conception à saisir si besoin | E41: =C41*C108+C109*D41 -> 0 | K41: =SUM(E41:J41)-F41-G41 -> 0 | L41: =E41*(1+C110)+I41+J41*(1+C112) -> 0 | M41: =E41*(1+C119)+I41+J41 -> 0
B42: Libellé libre phase de conception à saisir si besoin | E42: =C42*C108+C109*D42 -> 0 | K42: =SUM(E42:J42)-F42-G42 -> 0 | L42: =E42*(1+C110)+I42+J42*(1+C112) -> 0 | M42: =E42*(1+C119)+I42+J42 -> 0
B43: Libellé libre phase de conception à saisir si besoin | E43: =C43*C108+C109*D43 -> 0 | K43: =SUM(E43:J43)-F43-G43 -> 0 | L43: =E43*(1+C110)+I43+J43*(1+C112) -> 0 | M43: =E43*(1+C119)+I43+J43 -> 0
B44: Libellé libre phase de conception à saisir si besoin | E44: =C44*C108+C109*D44 -> 0 | K44: =SUM(E44:J44)-F44-G44 -> 0 | L44: =E44*(1+C110)+I44+J44*(1+C112) -> 0 | M44: =E44*(1+C119)+I44+J44 -> 0
B45: Rédaction cahier des charges pour sous-traitants | E45: =C45*C108+C109*D45 -> 0 | K45: =SUM(E45:J45)-F45-G45 -> 0 | L45: =E45*(1+C110)+I45+J45*(1+C112) -> 0 | M45: =E45*(1+C119)+I45+J45 -> 0
B46: Sélection et qualification des intervenants | E46: =C46*C108+C109*D46 -> 0 | K46: =SUM(E46:J46)-F46-G46 -> 0 | L46: =E46*(1+C110)+I46+J46*(1+C112) -> 0 | M46: =E46*(1+C119)+I46+J46 -> 0
...

Sheet Coûts installations part2
A1: Coût des installations
A3: TP - Coût par jour | B3: Coût HT | C3: Quantité | D3: Montant
A4: Chantier école CHE | B4: 1000 | D4: =B4*C4 -> 0
A5: Chantier école MAR | B5: 1000 | D5: =B5*C5 -> 0
A6: Chantier école SAC | B6: 1000 | D6: =B6*C6 -> 0
A7: EVOC | B7: 5000 | D7: =B7*C7 -> 0
A8: Radiochimie | B8: 1000 | D8: =B8*C8 -> 0
A9: Autre (préciser Coût HT) | D9: =B9*C9 -> 0
A10: Montant TP reporté sur fiche de coût | D10: =SUM(D4:D9) -> 0
A13: Montant salles /outils pédagos reporté sur fiche de coût | D13: =B18*C18+B19*C19+B20*C20+B21*C21+B22*C22+B23*C23+D18*E18+D19*E19+D20*E20+D21*E21+D22*E22+D23*E23+F18*G18+F19*G19+F20*G20+F21*G21+F22*G22+F23*G23+H18*I18+H19*I19+H20*I20+H21*I21+H22*I22+H23*I23+B29*C29+B30*C30+B31*C31+B32*C32+D29*E29+D30*E30+D31*E31+D32*E32+F29*G29+F30*G30+F31*G31+F32*G32+H29*I29+H30*I30+H31*I31+H32*I32+B37*C37+B38*C38+B39*C39+B40*C40+D37*E37+D38*E38+D39*E39+D40*E40+F37*G37+F38*G38+F39*G39+F40*G40+H37*I37+H38*I38+H39*I39+H40*I40+B45*C45+B46*C46+B47*C47+B48*C48+B49*C49+B50*C50+B51*C51+B52*C52+B54*C54+B55*C55+B56*C56+B57*C57+D45*E45+D46*E46+D47*E47+D48*E48+D49*E49+D50*E50+D51*E51+D52*E52+D54*E54+D55*E55+D56*E56+D57*E57+F45*G45+F46*G46+F47*G47+F48*G48+F49*G49+F50*G50+F51*G51+F52*G52+F53*G53+F54*G54+F55*G55+F56*G56+F57*G57+H45*I45+H46*I46+H47*I47+H48*I48+H49*I49+H50*I50+H51*I51+H52*I52+H53*I53+H54*I54+H55*I55+H56*I56+H57*I57+C61*D61+C62*D62+C63*D63+C64*D64+C65*D65+C66*D66+C67*D67+C68*D68+C69*D69+C70*D70+C71*D71+C72*D72+C73*D73+C74*D74+E61*F61+E62*F62+E63*F63+E64*F64+E65*F65+E66*F66+E67*F67+E68*F68+E69*F69+E70*F70+E71*F71+E72*F72+E73*F73+E74*F74 -> 0
B15: Jour | F15: 1/2 Jour
A16: Salles - valeurs moyennes | B16: Client non CEA | D16: Client CEA (remise 20%) | F16: Client non CEA | H16: Client CEA (remise 20%)
B17: Coût | C17: Quantité | D17: Coût | E17: Quantité | F17: Coût | G17: Quantité | H17: Coût | I17: Quantité
A18: Salle < 26 | B18: 370 | D18: =ROUND(B18*0.8,0) -> 296 | F18: =ROUND(B18*0.65,0) -> 241 | H18: =ROUND(F18*0.8,0) -> 193
A19: Salle < 50 | B19: 700 | D19: =ROUND(B19*0.8,0) -> 560 | F19: =ROUND(B19*0.65,0) -> 455 | H19: =ROUND(F19*0.8,0) -> 364
A20: Salle 50 à 80 cours | B20: 1050 | D20: =ROUND(B20*0.8,0) -> 840 | F20: =ROUND(B20*0.65,0) -> 683 | H20: =ROUND(F20*0.8,0) -> 546
A21: Salle > 80 | B21: 1300 | D21: =ROUND(B21*0.8,0) -> 1040 | F21: =ROUND(B21*0.65,0) -> 845 | H21: =ROUND(F21*0.8,0) -> 676
A22: Salle TP ou informatique | B22: 800 | D22: =ROUND(B22*0.8,0) -> 640 | F22: =ROUND(B22*0.65,0) -> 520 | H22: =ROUND(F22*0.8,0) -> 416
A23: Autre (préciser Coût HT) | D23: =ROUND(B23*0.8,0) -> 0 | F23: =ROUND(B23*0.65,0) -> 0 | H23: =ROUND(F23*0.8,0) -> 0
B26: Jour | F26: 1/2 Jour
A27: Salles UEC | B27: Client non CEA | D27: Client CEA (remise 20%) | F27: Client non CEA | H27: Client CEA (remise 20%)
B28: Coût | C28: Quantité | D28: Coût | E28: Quantité | F28: Coût | G28: Quantité | H28: Coût | I28: Quantité
A29: Amphi | B29: 1600 | D29: =ROUND(B29*0.8,0) -> 1280 | F29: 900 | H29: =ROUND(F29*0.8,0) -> 720
A30: H1 | B30: 550 | D30: =ROUND(B30*0.8,0) -> 440 | F30: 350 | H30: =ROUND(F30*0.8,0) -> 280
A31: H2 | B31: 420 | D31: =ROUND(B31*0.8,0) -> 336 | F31: 270 | H31: =ROUND(F31*0.8,0) -> 216
A32: Autres salles UEC | B32: 440 | D32: =ROUND(B32*0.8,0) -> 352 | F32: 290 | H32: =ROUND(F32*0.8,0) -> 232
B34: Jour | F34: 1/2 Jour
A35: Salles UEM | B35: Client non CEA | D35: Client CEA (remise 20%) | F35: Client non CEA | H35: Client CEA (remise 20%)
B36: Coût | C36: Quantité | D36: Coût | E36: Quantité | F36: Coût | G36: Quantité | H36: Coût | I36: Quantité
A37: Salle de cours 40 personnes | B37: 500 | D37: =ROUND(B37*0.8,0) -> 400 | F37: 300 | H37: =ROUND(F37*0.8,0) -> 240
A38: Salle de cours 30 personnes | B38: 400 | D38: =ROUND(B38*0.8,0) -> 320 | F38: 250 | H38: =ROUND(F38*0.8,0) -> 200
A39: Salle de cours 19 personnes | B39: 400 | D39: =ROUND(B39*0.8,0) -> 320 | F39: 250 | H39: =ROUND(F39*0.8,0) -> 200
A40: Salle informatique 8 PC | B40: 620 | D40: =ROUND(B40*0.8,0) -> 496 | F40: 370 | H40: =ROUND(F40*0.8,0) -> 296
B42: Jour | F42: 1/2 Jour
A43: Salles UES | B43: Client non CEA | D43: Client CEA (remise 20%) | F43: Client non CEA | H43: Client CEA (remise 20%)
B44: Coût | C44: Quantité | D44: Coût | E44: Quantité | F44: Coût | G44: Quantité | H44: Coût | I44: Quantité
A45: Salle de cours < 26 places écoles | B45: 370 | D45: =ROUND(B45*0.8,0) -> 296 | F45: 222 | H45: =ROUND(F45*0.8,0) -> 178
A46: Salle de cours < 50 places écoles | B46: 700 | D46: =ROUND(B46*0.8,0) -> 560 | F46: 420 | H46: =ROUND(F46*0.8,0) -> 336
A47: Salle de cours de 72 à 80 places écoles | B47: 1050 | D47: =ROUND(B47*0.8,0) -> 840 | F47: 630 | H47: =ROUND(F47*0.8,0) -> 504
A48: Salle Eichner 120 places écoles | B48: 1300 | D48: =ROUND(B48*0.8,0) -> 1040 | F48: 780 | H48: =ROUND(F48*0.8,0) -> 624
...

Sheet Coûts frais variables part2
A1: Coûts frais variables
A3: Repas - coût unitaire | B3: Coût unitaire HT | C3: Nombre de pauses par participant sur l'ensemble de la formation | D3: Nombre Participants saisi sur fiche de coût | E3: Montant
A4: Repas Rotonde (participants + 2) | B4: 17.5 | D4: ='Fiche de coûts part2'!C14+2 -> 9 | E4: =B4*D4*C4 -> 0
A5: Repas restaurant (participants + 2) | B5: 12.5 | D5: ='Fiche de coûts part2'!C14+2 -> 9 | E5: =B5*D5*C5 -> 0
A6: Pause café standard | B6: 6 | D6: ='Fiche de coûts part2'!C14 -> 7 | E6: =B6*D6*C6 -> 0
A7: Autre (préciser prix HT) | D7: ='Fiche de coûts part2'!C14 -> 7 | E7: =B7*D7*C7 -> 0
A8: Montant repas reporté sur fiche de coût | E8: =SUM(E4:E7) -> 0
A11: Supports de formation - coût unitaire | B11: Coût unitaire HT | C11: Nombre de supports ou de matériel par participant | D11: Nombre Participants saisi sur fiche de coût | E11: Montant reporté sur fiche de coût
A12: Supports de formation (livres, CD, clés USB, tablettes…) (prix unitaire à corriger si besoin) | B12: 15 | D12: ='Fiche de coûts part2'!C14 -> 7 | E12: =B12*D12*C12 -> 0
A13: Polycopiés (100 pages par participant) | B13: 25 | D13: ='Fiche de coûts part2'!C14 -> 7 | E13: =B13*D13*C13 -> 0
A14: Pochettes ou boîtes | B14: 5 | D14: ='Fiche de coûts part2'!C14 -> 7 | E14: =B14*D14*C14 -> 0
A15: Autre support de formation(préciser prix HT) | D15: ='Fiche de coûts part2'!C14 -> 7 | E15: =B15*D15*C15 -> 0
A16: Libellé libre frais variable à saisir si besoin (onglet frais var) | D16: ='Fiche de coûts part2'!C14 -> 7 | E16: =B16*D16*C16 -> 0
A17: Libellé libre frais variable à saisir si besoin (onglet frais var) | D17: ='Fiche de coûts part2'!C14 -> 7 | E17: =B17*D17*C17 -> 0
A18: Libellé libre frais variable à saisir si besoin (onglet frais var) | D18: ='Fiche de coûts part2'!C14 -> 7 | E18: =B18*D18*C18 -> 0
A19: Libellé libre frais variable à saisir si besoin (onglet frais var) | D19: ='Fiche de coûts part2'!C14 -> 7 | E19: =B19*D19*C19 -> 0

Sheet Coûts frais déplacement part2
A1: Coûts frais de déplacement
A2: (aide pour le chiffrage : barème CEA)
C5: Région parisienne | E5: Province | G5: Etranger | I5: Montant à reporter sur fiche de coût
A6: Type de frais | B6: Unité | C6: Coût | D6: Quantité | E6: Coût | F6: Quantité | G6: Coût | H6: Quantité
A7: Frais de déplacement | B7: km | C7: 0.32 | E7: 0.32 | G7: 0 | I7: =C7*D7+E7*F7+G7*H7 -> 0
A8: Hébergement | B8: nuitée | C8: 92 | E8: 72 | G8: 0 | I8: =C8*D8+E8*F8+G8*H8 -> 0
A9: Restauration soir | B9: EUR | C9: 22 | E9: 22 | G9: 0 | I9: =C9*D9+E9*F9+G9*H9 -> 0
A10: Restauration midi | B10: EUR | C10: 17.5 | E10: 17.5 | G10: 0 | I10: =C10*D10+E10*F10+G10*H10 -> 0
A11: Autre (préciser prix HT) | B11: EUR | E11: =ROUND(C11*0.65,0) -> 0 | G11: =ROUND(E11*0.65,0) -> 0 | I11: =C11*D11+E11*F11+G11*H11 -> 0
I12: =SUM(I7:I11) -> 0
A13: Attention : montants qui ne remontent pas dans la fiche de coût (simple aide à la saisie)

Sheet Fiche de coûts conso
A1: ='Fiche de coûts part2'!A1:M1 -> Fiche de coûts INSTN - V1.4 du 25/01/2019
C3: Consolidation Unité Pilote + Partenaire 1 + Partenaire 2
B5: Libellé de la formation ou de la prestation | C5: ='Fiche de coûts'!C5:F5 -> Télémanipulation | J5: Prix de vente CEA | K5: Prix de vente hors CEA minimum | L5: =CONCATENATE("Prix de vente hors CEA préconisé avec taux de marge de ",C15*100,"%") -> Prix de vente hors CEA préconisé avec taux de marge de 10%
B6: Code IRIS de la formation (si existant, sinon ne rien indiquer) | C6: ='Fiche de coûts'!C6 -> TEL | G6: Coût par session / prestation hors aléas | J6: =K29 -> 6334.06 | K6: =L29 -> 8400.9272 | L6: =K6*(1+C15) -> 9241.0199
B7: Date de création de la formation (JJ/MM/AAAA) | C7: ='Fiche de coûts'!C7 -> 36161 | G7: Dont part fixe | J7: =K53+K97-K80-K81-K82-K83-K84-K85-K86-K87-K88 -> 2409.06 | K7: =L53+L97-L80-L81-L82-L83-L84-L85-L86-L87-L88 -> 4342.4772 | L7: =K7*(1+C15) -> 4776.7249
B8: Type de formation (menu déroulant) | C8: ='Fiche de coûts'!C8 -> FC INTER | G8: Dont part variable | J8: =K80+K81+K82+K83+K84+K85+K86+K87+K88 -> 3925 | K8: =L80+L81+L82+L83+L84+L85+L86+L87+L88 -> 4058.45 | L8: =K8*(1+C15) -> 4464.295
B9: Durée de la session en jours (pour formation continue) | C9: ='Fiche de coûts'!C9 -> 3 | G9: Aléas 10% | J9: =ROUND(J6*0.1,0) -> 633 | K9: =ROUND(K6*0.1,0) -> 840 | L9: =ROUND(L6*0.1,0) -> 924
B10: Nom du responsable pédagogique | C10: ='Fiche de coûts'!C10 -> J.VIDECOQ | G10: Coût par session avec aléas | J10: =J6+J9 -> 6967.06 | K10: =K6+K9 -> 9240.9272 | L10: =L6+L9 -> 10165.02
B11: Code OS de la formation (menu déroulant lié à onglet "table OS") | C11: ='Fiche de coûts'!C11:E11 -> LOCTHEXPMAIN | G11: Coût par participant | J11: =ROUND(J10/C14,0) -> 995 | K11: =ROUND(K10/C14,0) -> 1320 | L11: =ROUND(L10/C14,0) -> 1452
B12: Numéro de programme ou projet INSTN (lien auto si OS renseigné) | C12: ='Fiche de coûts'!C12 -> Projet 06 | G12: Coût par jour | J12: =IF(OR(LEFT(C8,2)="FC",LEFT(C8,2)="Ce"),ROUND(J10/C9,0),"Non applicable") -> 2322 | K12: =IF(OR(LEFT(C8,2)="FC",LEFT(C8,2)="Ce"),ROUND(K10/C9,0),"Non applicable") -> 3080 | L12: =IF(OR(LEFT(C8,2)="FC",LEFT(C8,2)="Ce"),ROUND(L10/C9,0),"Non applicable") -> 3388
B13: Unités INSTN*** | C13: Saisir différentes unités concernées | G13: Coût par jour et par participant | J13: =IF(LEFT(J12,1)="N",J12,ROUND(J12/C14,0)) -> 332 | K13: =IF(LEFT(K12,1)="N",K12,ROUND(K12/C14,0)) -> 440 | L13: =IF(LEFT(L12,1)="N",L12,ROUND(L12/C14,0)) -> 484
B14: Nombre de participants prévu | C14: ='Fiche de coûts'!C14 -> 7 | G14: Nombre de participants minimum | J14: =ROUNDUP(J7/(J11-J8/C14),0) -> 6 | K14: =ROUNDUP(J7/(K11-J8/C14),0) -> 4 | L14: =ROUNDUP(J7/(L11-J8/C14),0) -> 3
B15: Taux de marge pour prix de vente hors CEA préconisé | C15: ='Fiche de coûts'!C15 -> 0.1 | D15: Taux de marge de 10% à | G15: CA pour nombre participants minimum | J15: =J11*J14 -> 5970 | K15: =K11*K14 -> 5280 | L15: =L11*L14 -> 4356
D16: modifier si nécessaire | G16: Coût T1 pour participants minimum | J16: =ROUND(J7+J8/C14*J14,0) -> 5773 | K16: =ROUND(J7+J8/C14*K14,0) -> 4652 | L16: =ROUND(J7+J8/C14*L14,0) -> 4091
B17: *** si plusieurs unités, saisir une fiche de coût par unité et voir vision complète sur feuille "fiche de coût conso" | G17: Prix de vente définitif client CEA fixé | J17: A saisir | K17: Dont partenaires 1+2 : | M17: =IF(AND('Fiche de coûts part1'!J17="A saisir",'Fiche de coûts part2'!J17="A saisir"),"Non renseigné",IF('Fiche de coûts part2'!J17<>"A saisir",'Fiche de coûts part1'!J17+'Fiche de coûts part2'!J17,'Fiche de coûts part1'!J17)) -> Non renseigné
G18: Prix de vente définitif client externe fixé | J18: A saisir | K18: Dont partenaires 1+2 : | M18: =IF(AND('Fiche de coûts part1'!J18="A saisir",'Fiche de coûts part2'!J18="A saisir"),"Non renseigné",IF('Fiche de coûts part2'!J18<>"A saisir",'Fiche de coûts part1'!J18+'Fiche de coûts part2'!J18,'Fiche de coûts part1'!J18)) -> Non renseigné
G20: En cas d'exclusion du coût de conception des chiffrages ci-dessus (ie. si durée amo conception choisie = 0) :
G21: Montant total de conception à facturer | J21: =IF(I50=0,K49,0) -> 0 | K21: =IF(I50=0,L49,0) -> 0 | L21: =IF(I50=0,M49,0) -> 0
G22: Soit montant de conception par jour | J22: =IF(OR(LEFT(C8,2)="FC",LEFT(C8,2)="Ce"),ROUND(J21/C9,0),"Non applicable") -> 0 | K22: =IF(OR(LEFT(C8,2)="FC",LEFT(C8,2)="Ce"),ROUND(K21/C9,0),"Non applicable") -> 0 | L22: =IF(OR(LEFT(C8,2)="FC",LEFT(C8,2)="Ce"),ROUND(L21/C9,0),"Non applicable") -> 0
G23: Soit montant de conception par participant | J23: =J21/C14 -> 0 | K23: =K21/C14 -> 0 | L23: =L21/C14 -> 0
